Workbook
Name _200111_1926_Perceptron_Brown: 'Comparativa ce01'!$A$20:$K$369
Name _200112_2142_TnT_Brown: 'Comparativa ce01'!#REF!
Name _200112_2142_TnT_Brown__1: 'Comparativa ce01'!$AF$20:$AH$369

Sheet Comparativa ce01
A5: palabra desconocida mal etiquetada por los 3 etiquetadores
A6: palabra desconocida solo mal etiquetada por TNT
A7: palabra desconocida mal etiquetada por TNT y Perceptron
A8: palabra desconocida mal etiquetada por TNT y Stanford
I9: Brown | J9: Universal | Q9: Brown | R9: Universal | Y9: Brown | Z9: Universal | AF9: Brown | AG9: Universal
A10: Total etiquetas | I10: =COUNTA(I$20:I$989) -> 350 | J10: =COUNTA($G$20:$G$989) -> 350 | Q10: =COUNTA(Q20:Q1000) -> 350 | R10: =COUNTA($G20:$G1000) -> 350 | Y10: =COUNTA(Y$20:Y$989) -> 350 | Z10: =COUNTA($G$20:$G$989) -> 350 | AF10: =COUNTA(AF$20:AF$989) -> 350 | AG10: =COUNTA($G$20:$G$989) -> 350
A11: Aciertos | I11: =SUM(M$20:M$989) -> 317 | J11: =SUM(N$20:N$989) -> 323 | Q11: =SUM(U20:U369) -> 293 | R11: =SUM(V20:V1000) -> 306 | Y11: =SUM(AC$20:AC$989) -> 323 | Z11: =SUM(AD$20:AD$989) -> 328 | AF11: =SUM(AJ$20:AJ$989) -> 301 | AG11: =SUM(AK$20:AK$989) -> 303
A12: % | I12: =I11/I10 -> 0.90571429 | J12: =J11/J10 -> 0.92285714 | Q12: =Q11/Q10 -> 0.83714286 | R12: =R11/R10 -> 0.87428571 | Y12: =Y11/Y10 -> 0.92285714 | Z12: =Z11/Z10 -> 0.93714286 | AF12: =AF11/AF10 -> 0.86 | AG12: =AG11/AG10 -> 0.86571429
A13: Total palabras deconocidas | I13: =COUNTIFS($AF$20:$AF989,"Unk") -> 40 | J13: =COUNTIFS($AF$20:$AF989,"Unk") -> 40 | Y13: =COUNTIFS($AF$20:$AF989,"Unk") -> 40 | Z13: =COUNTIFS($AF$20:$AF989,"Unk") -> 40 | AF13: =COUNTIFS($AF$20:$AF989,"Unk") -> 40 | AG13: =COUNTIFS($AF$20:$AF989,"Unk") -> 40
A14: Aciertos | I14: =SUMIFS(M$20:M$987,$AF$20:$AF$987,"Unk") -> 23 | J14: =SUMIFS(N$20:N$987,$AF$20:$AF$987,"Unk") -> 26 | Y14: =SUMIFS(AC$20:AC$987,$AF$20:$AF$987,"Unk") -> 27 | Z14: =SUMIFS(AD$20:AD$987,$AF$20:$AF$987,"Unk") -> 29 | AF14: =SUMIFS(AJ$20:AJ$987,$AF$20:$AF$987,"Unk") -> 0 | AG14: =SUMIFS(AK$20:AK$987,$AF$20:$AF$987,"Unk") -> 0
A15: % | I15: =I14/I13 -> 0.575 | J15: =J14/J13 -> 0.65 | Q15: =Q14/Q13 -> #DIV/0! | R15: =R14/R13 -> #DIV/0! | Y15: =Y14/Y13 -> 0.675 | Z15: =Z14/Z13 -> 0.725 | AF15: =AF14/AF13 -> 0 | AG15: =AG14/AG13 -> 0
A16: Parte del error debido a palabras desconocidas | I16: =(I13-I14)/I10 -> 0.048571429 | J16: =(J13-J14)/J10 -> 0.04 | Y16: =(Y13-Y14)/Y10 -> 0.037142857 | Z16: =(Z13-Z14)/Z10 -> 0.031428571 | AF16: =(AF13-AF14)/AF10 -> 0.11428571 | AG16: =(AG13-AG14)/AG10 -> 0.11428571
I18: =I16*2 -> 0.097142857
A19: Text, P original | B19: Es ADJ | C19: Es ADV | D19: Gold, Brown tagset | G19: Gold, Universal (manual) | I19: Perceptron, Brown tagset | K19: Perceptron, Universal (NLTK) | L19: Perceptron, Universal (manual) | M19: Right Brown | N19: Right Universal | P19: Text, S tagged | Q19: Stanford 3000, Brown tagset | T19: Standford, Universal (manual) | U19: Right Brown | V19: Right Universal | X19: Text, S tagged | Y19: Stanford 20000, Brown tagset | AB19: Standford, Universal (manual) | AC19: Right Brown | AD19: Right Universal | AF19: TnT, Brown tagset | AH19: TnT, Universal | AJ19: Right Brown | AK19: Right Universal | AM19: Total Brown | AN19: Total univ
A20: Too | C20: 1 | D20: QL | E20: =INDEX('Brown tagset'!$B:$B,MATCH(IF(ISERROR(FIND("-",D20)),IF(ISERROR(FIND("+",D20)),D20,LEFT(D20,FIND("+",D20)-1)),LEFT(D20,FIND("-",D20)-1)),'Brown tagset'!$A:$A,0)) -> qualifier (very, fairly) | G20: =INDEX('Brown-Universal mapping'!$B:$B,MATCH(D20,'Brown-Universal mapping'!$A:$A,0)) -> ADV | I20: QL | J20: =INDEX('Brown tagset'!$B:$B,MATCH(IF(ISERROR(FIND("-",I20)),IF(ISERROR(FIND("+",I20)),I20,LEFT(I20,FIND("+",I20)-1)),LEFT(I20,FIND("-",I20)-1)),'Brown tagset'!$A:$A,0)) -> qualifier (very, fairly) | K20: X | L20: =INDEX('Brown-Universal mapping'!$B:$B,MATCH(I20,'Brown-Universal mapping'!$A:$A,0)) -> ADV | M20: =IF(I20=$D20,1,0) -> 1 | N20: =IF(L20=$G20,1,0) -> 1 | P20: Too | Q20: np | R20: =INDEX('Brown tagset'!$B:$B,MATCH(IF(ISERROR(FIND("-",Q20)),IF(ISERROR(FIND("+",Q20)),Q20,LEFT(Q20,FIND("+",Q20)-1)),LEFT(Q20,FIND("-",Q20)-1)),'Brown tagset'!$A:$A,0)) -> proper noun or part of name phrase | T20: =INDEX('Brown-Universal mapping'!$B:$B,MATCH(Q20,'Brown-Universal mapping'!$A:$A,0)) -> NOUN | U20: =IF(Q20=$D20,1,0) -> 0 | V20: =IF(T20=$G20,1,0) -> 0 | X20: Too | Y20: ql | Z20: =INDEX('Brown tagset'!$B:$B,MATCH(IF(ISERROR(FIND("-",Y20)),IF(ISERROR(FIND("+",Y20)),Y20,LEFT(Y20,FIND("+",Y20)-1)),LEFT(Y20,FIND("-",Y20)-1)),'Brown tagset'!$A:$A,0)) -> qualifier (very, fairly) | AB20: =INDEX('Brown-Universal mapping'!$B:$B,MATCH(Y20,'Brown-Universal mapping'!$A:$A,0)) -> ADV | AC20: =IF(Y20=$D20,1,0) -> 1 | AD20: =IF(AB20=$G20,1,0) -> 1 | AF20: QL | AG20: =INDEX('Brown tagset'!$B:$B,MATCH(IF(ISERROR(FIND("-",AF20)),IF(ISERROR(FIND("+",AF20)),AF20,LEFT(AF20,FIND("+",AF20)-1)),LEFT(AF20,FIND("-",AF20)-1)),'Brown tagset'!$A:$A,0)) -> qualifier (very, fairly) | AH20: X | AI20: =INDEX('Brown-Universal mapping'!$B:$B,MATCH(AF20,'Brown-Universal mapping'!$A:$A,0)) -> ADV | AJ20: =IF(AF20=$D20,1,0) -> 1 | AK20: =IF(AI20=$G20,1,0) -> 1 | AM20: =M20+AC20+AJ20 -> 3 | AN20: =N20+AD20+AK20 -> 3 | AP20: =AG20&AM20 -> qualifier (very, fairly)3
A21: often | C21: 1 | D21: RB | E21: =INDEX('Brown tagset'!$B:$B,MATCH(IF(ISERROR(FIND("-",D21)),IF(ISERROR(FIND("+",D21)),D21,LEFT(D21,FIND("+",D21)-1)),LEFT(D21,FIND("-",D21)-1)),'Brown tagset'!$A:$A,0)) -> adverb | G21: =INDEX('Brown-Universal mapping'!$B:$B,MATCH(D21,'Brown-Universal mapping'!$A:$A,0)) -> ADV | I21: RB | J21: =INDEX('Brown tagset'!$B:$B,MATCH(IF(ISERROR(FIND("-",I21)),IF(ISERROR(FIND("+",I21)),I21,LEFT(I21,FIND("+",I21)-1)),LEFT(I21,FIND("-",I21)-1)),'Brown tagset'!$A:$A,0)) -> adverb | K21: ADV | L21: =INDEX('Brown-Universal mapping'!$B:$B,MATCH(I21,'Brown-Universal mapping'!$A:$A,0)) -> ADV | M21: =IF(I21=$D21,1,0) -> 1 | N21: =IF(L21=$G21,1,0) -> 1 | P21: often | Q21: rb | R21: =INDEX('Brown tagset'!$B:$B,MATCH(IF(ISERROR(FIND("-",Q21)),IF(ISERROR(FIND("+",Q21)),Q21,LEFT(Q21,FIND("+",Q21)-1)),LEFT(Q21,FIND("-",Q21)-1)),'Brown tagset'!$A:$A,0)) -> adverb | T21: =INDEX('Brown-Universal mapping'!$B:$B,MATCH(Q21,'Brown-Universal mapping'!$A:$A,0)) -> ADV | U21: =IF(Q21=$D21,1,0) -> 1 | V21: =IF(T21=$G21,1,0) -> 1 | X21: often | Y21: rb | Z21: =INDEX('Brown tagset'!$B:$B,MATCH(IF(ISERROR(FIND("-",Y21)),IF(ISERROR(FIND("+",Y21)),Y21,LEFT(Y21,FIND("+",Y21)-1)),LEFT(Y21,FIND("-",Y21)-1)),'Brown tagset'!$A:$A,0)) -> adverb | AB21: =INDEX('Brown-Universal mapping'!$B:$B,MATCH(Y21,'Brown-Universal mapping'!$A:$A,0)) -> ADV | AC21: =IF(Y21=$D21,1,0) -> 1 | AD21: =IF(AB21=$G21,1,0) -> 1 | AF21: RB | AG21: =INDEX('Brown tagset'!$B:$B,MATCH(IF(ISERROR(FIND("-",AF21)),IF(ISERROR(FIND("+",AF21)),AF21,LEFT(AF21,FIND("+",AF21)-1)),LEFT(AF21,FIND("-",AF21)-1)),'Brown tagset'!$A:$A,0)) -> adverb | AH21: ADV | AI21: =INDEX('Brown-Universal mapping'!$B:$B,MATCH(AF21,'Brown-Universal mapping'!$A:$A,0)) -> ADV | AJ21: =IF(AF21=$D21,1,0) -> 1 | AK21: =IF(AI21=$G21,1,0) -> 1 | AM21: =M21+AC21+AJ21 -> 3 | AN21: =N21+AD21+AK21 -> 3 | AP21: =AG21&AM21 -> adverb3
A22: a | D22: AT | E22: =INDEX('Brown tagset'!$B:$B,MATCH(IF(ISERROR(FIND("-",D22)),IF(ISERROR(FIND("+",D22)),D22,LEFT(D22,FIND("+",D22)-1)),LEFT(D22,FIND("-",D22)-1)),'Brown tagset'!$A:$A,0)) -> article (a, the, no) | G22: =INDEX('Brown-Universal mapping'!$B:$B,MATCH(D22,'Brown-Universal mapping'!$A:$A,0)) -> DET | I22: AT | J22: =INDEX('Brown tagset'!$B:$B,MATCH(IF(ISERROR(FIND("-",I22)),IF(ISERROR(FIND("+",I22)),I22,LEFT(I22,FIND("+",I22)-1)),LEFT(I22,FIND("-",I22)-1)),'Brown tagset'!$A:$A,0)) -> article (a, the, no) | K22: X | L22: =INDEX('Brown-Universal mapping'!$B:$B,MATCH(I22,'Brown-Universal mapping'!$A:$A,0)) -> DET | M22: =IF(I22=$D22,1,0) -> 1 | N22: =IF(L22=$G22,1,0) -> 1 | P22: a | Q22: at | R22: =INDEX('Brown tagset'!$B:$B,MATCH(IF(ISERROR(FIND("-",Q22)),IF(ISERROR(FIND("+",Q22)),Q22,LEFT(Q22,FIND("+",Q22)-1)),LEFT(Q22,FIND("-",Q22)-1)),'Brown tagset'!$A:$A,0)) -> article (a, the, no) | T22: =INDEX('Brown-Universal mapping'!$B:$B,MATCH(Q22,'Brown-Universal mapping'!$A:$A,0)) -> DET | U22: =IF(Q22=$D22,1,0) -> 1 | V22: =IF(T22=$G22,1,0) -> 1 | X22: a | Y22: at | Z22: =INDEX('Brown tagset'!$B:$B,MATCH(IF(ISERROR(FIND("-",Y22)),IF(ISERROR(FIND("+",Y22)),Y22,LEFT(Y22,FIND("+",Y22)-1)),LEFT(Y22,FIND("-",Y22)-1)),'Brown tagset'!$A:$A,0)) -> article (a, the, no) | AB22: =INDEX('Brown-Universal mapping'!$B:$B,MATCH(Y22,'Brown-Universal mapping'!$A:$A,0)) -> DET | AC22: =IF(Y22=$D22,1,0) -> 1 | AD22: =IF(AB22=$G22,1,0) -> 1 | AF22: AT | AG22: =INDEX('Brown tagset'!$B:$B,MATCH(IF(ISERROR(FIND("-",AF22)),IF(ISERROR(FIND("+",AF22)),AF22,LEFT(AF22,FIND("+",AF22)-1)),LEFT(AF22,FIND("-",AF22)-1)),'Brown tagset'!$A:$A,0)) -> article (a, the, no) | AH22: X | AI22: =INDEX('Brown-Universal mapping'!$B:$B,MATCH(AF22,'Brown-Universal mapping'!$A:$A,0)) -> DET | AJ22: =IF(AF22=$D22,1,0) -> 1 | AK22: =IF(AI22=$G22,1,0) -> 1 | AM22: =M22+AC22+AJ22 -> 3 | AN22: =N22+AD22+AK22 -> 3 | AP22: =AG22&AM22 -> article (a, the, no)3
A23: beginning | D23: VBG | E23: =INDEX('Brown tagset'!$B:$B,MATCH(IF(ISERROR(FIND("-",D23)),IF(ISERROR(FIND("+",D23)),D23,LEFT(D23,FIND("+",D23)-1)),LEFT(D23,FIND("-",D23)-1)),'Brown tagset'!$A:$A,0)) -> verb, present participle/gerund | G23: =INDEX('Brown-Universal mapping'!$B:$B,MATCH(D23,'Brown-Universal mapping'!$A:$A,0)) -> VERB | I23: VBG | J23: =INDEX('Brown tagset'!$B:$B,MATCH(IF(ISERROR(FIND("-",I23)),IF(ISERROR(FIND("+",I23)),I23,LEFT(I23,FIND("+",I23)-1)),LEFT(I23,FIND("-",I23)-1)),'Brown tagset'!$A:$A,0)) -> verb, present participle/gerund | K23: VERB | L23: =INDEX('Brown-Universal mapping'!$B:$B,MATCH(I23,'Brown-Universal mapping'!$A:$A,0)) -> VERB | M23: =IF(I23=$D23,1,0) -> 1 | N23: =IF(L23=$G23,1,0) -> 1 | P23: beginning | Q23: nn | R23: =INDEX('Brown tagset'!$B:$B,MATCH(IF(ISERROR(FIND("-",Q23)),IF(ISERROR(FIND("+",Q23)),Q23,LEFT(Q23,FIND("+",Q23)-1)),LEFT(Q23,FIND("-",Q23)-1)),'Brown tagset'!$A:$A,0)) -> singular or mass noun | T23: =INDEX('Brown-Universal mapping'!$B:$B,MATCH(Q23,'Brown-Universal mapping'!$A:$A,0)) -> NOUN | U23: =IF(Q23=$D23,1,0) -> 0 | V23: =IF(T23=$G23,1,0) -> 0 | X23: beginning | Y23: nn | Z23: =INDEX('Brown tagset'!$B:$B,MATCH(IF(ISERROR(FIND("-",Y23)),IF(ISERROR(FIND("+",Y23)),Y23,LEFT(Y23,FIND("+",Y23)-1)),LEFT(Y23,FIND("-",Y23)-1)),'Brown tagset'!$A:$A,0)) -> singular or mass noun | AB23: =INDEX('Brown-Universal mapping'!$B:$B,MATCH(Y23,'Brown-Universal mapping'!$A:$A,0)) -> NOUN | AC23: =IF(Y23=$D23,1,0) -> 0 | AD23: =IF(AB23=$G23,1,0) -> 0 | AF23: NN | AG23: =INDEX('Brown tagset'!$B:$B,MATCH(IF(ISERROR(FIND("-",AF23)),IF(ISERROR(FIND("+",AF23)),AF23,LEFT(AF23,FIND("+",AF23)-1)),LEFT(AF23,FIND("-",AF23)-1)),'Brown tagset'!$A:$A,0)) -> singular or mass noun | AH23: NOUN | AI23: =INDEX('Brown-Universal mapping'!$B:$B,MATCH(AF23,'Brown-Universal mapping'!$A:$A,0)) -> NOUN | AJ23: =IF(AF23=$D23,1,0) -> 0 | AK23: =IF(AI23=$G23,1,0) -> 0 | AM23: =M23+AC23+AJ23 -> 1 | AN23: =N23+AD23+AK23 -> 1 | AP23: =AG23&AM23 -> singular or mass noun1
A24: bodybuilder | D24: NN | E24: =INDEX('Brown tagset'!$B:$B,MATCH(IF(ISERROR(FIND("-",D24)),IF(ISERROR(FIND("+",D24)),D24,LEFT(D24,FIND("+",D24)-1)),LEFT(D24,FIND("-",D24)-1)),'Brown tagset'!$A:$A,0)) -> singular or mass noun | G24: =INDEX('Brown-Universal mapping'!$B:$B,MATCH(D24,'Brown-Universal mapping'!$A:$A,0)) -> NOUN | I24: NN | J24: =INDEX('Brown tagset'!$B:$B,MATCH(IF(ISERROR(FIND("-",I24)),IF(ISERROR(FIND("+",I24)),I24,LEFT(I24,FIND("+",I24)-1)),LEFT(I24,FIND("-",I24)-1)),'Brown tagset'!$A:$A,0)) -> singular or mass noun | K24: NOUN | L24: =INDEX('Brown-Universal mapping'!$B:$B,MATCH(I24,'Brown-Universal mapping'!$A:$A,0)) -> NOUN | M24: =IF(I24=$D24,1,0) -> 1 | N24: =IF(L24=$G24,1,0) -> 1 | P24: bodybuilder | Q24: nn | R24: =INDEX('Brown tagset'!$B:$B,MATCH(IF(ISERROR(FIND("-",Q24)),IF(ISERROR(FIND("+",Q24)),Q24,LEFT(Q24,FIND("+",Q24)-1)),LEFT(Q24,FIND("-",Q24)-1)),'Brown tagset'!$A:$A,0)) -> singular or mass noun | T24: =INDEX('Brown-Universal mapping'!$B:$B,MATCH(Q24,'Brown-Universal mapping'!$A:$A,0)) -> NOUN | U24: =IF(Q24=$D24,1,0) -> 1 | V24: =IF(T24=$G24,1,0) -> 1 | X24: bodybuilder | Y24: nn | Z24: =INDEX('Brown tagset'!$B:$B,MATCH(IF(ISERROR(FIND("-",Y24)),IF(ISERROR(FIND("+",Y24)),Y24,LEFT(Y24,FIND("+",Y24)-1)),LEFT(Y24,FIND("-",Y24)-1)),'Brown tagset'!$A:$A,0)) -> singular or mass noun | AB24: =INDEX('Brown-Universal mapping'!$B:$B,MATCH(Y24,'Brown-Universal mapping'!$A:$A,0)) -> NOUN | AC24: =IF(Y24=$D24,1,0) -> 1 | AD24: =IF(AB24=$G24,1,0) -> 1 | AF24: Unk | AG24: =INDEX('Brown tagset'!$B:$B,MATCH(IF(ISERROR(FIND("-",AF24)),IF(ISERROR(FIND("+",AF24)),AF24,LEFT(AF24,FIND("+",AF24)-1)),LEFT(AF24,FIND("-",AF24)-1)),'Brown tagset'!$A:$A,0)) -> unknown | AH24: X | AI24: =INDEX('Brown-Universal mapping'!$B:$B,MATCH(AF24,'Brown-Universal mapping'!$A:$A,0)) -> Unknown | AJ24: =IF(AF24=$D24,1,0) -> 0 | AK24: =IF(AI24=$G24,1,0) -> 0 | AM24: =M24+AC24+AJ24 -> 2 | AN24: =N24+AD24+AK24 -> 2 | AP24: =AG24&AM24 -> unknown2
A25: has | D25: HVZ | E25: =INDEX('Brown tagset'!$B:$B,MATCH(IF(ISERROR(FIND("-",D25)),IF(ISERROR(FIND("+",D25)),D25,LEFT(D25,FIND("+",D25)-1)),LEFT(D25,FIND("-",D25)-1)),'Brown tagset'!$A:$A,0)) -> has | G25: =INDEX('Brown-Universal mapping'!$B:$B,MATCH(D25,'Brown-Universal mapping'!$A:$A,0)) -> VERB | I25: HVZ | J25: =INDEX('Brown tagset'!$B:$B,MATCH(IF(ISERROR(FIND("-",I25)),IF(ISERROR(FIND("+",I25)),I25,LEFT(I25,FIND("+",I25)-1)),LEFT(I25,FIND("-",I25)-1)),'Brown tagset'!$A:$A,0)) -> has | K25: X | L25: =INDEX('Brown-Universal mapping'!$B:$B,MATCH(I25,'Brown-Universal mapping'!$A:$A,0)) -> VERB | M25: =IF(I25=$D25,1,0) -> 1 | N25: =IF(L25=$G25,1,0) -> 1 | P25: has | Q25: hvz | R25: =INDEX('Brown tagset'!$B:$B,MATCH(IF(ISERROR(FIND("-",Q25)),IF(ISERROR(FIND("+",Q25)),Q25,LEFT(Q25,FIND("+",Q25)-1)),LEFT(Q25,FIND("-",Q25)-1)),'Brown tagset'!$A:$A,0)) -> has | T25: =INDEX('Brown-Universal mapping'!$B:$B,MATCH(Q25,'Brown-Universal mapping'!$A:$A,0)) -> VERB | U25: =IF(Q25=$D25,1,0) -> 1 | V25: =IF(T25=$G25,1,0) -> 1 | X25: has | Y25: hvz | Z25: =INDEX('Brown tagset'!$B:$B,MATCH(IF(ISERROR(FIND("-",Y25)),IF(ISERROR(FIND("+",Y25)),Y25,LEFT(Y25,FIND("+",Y25)-1)),LEFT(Y25,FIND("-",Y25)-1)),'Brown tagset'!$A:$A,0)) -> has | AB25: =INDEX('Brown-Universal mapping'!$B:$B,MATCH(Y25,'Brown-Universal mapping'!$A:$A,0)) -> VERB | AC25: =IF(Y25=$D25,1,0) -> 1 | AD25: =IF(AB25=$G25,1,0) -> 1 | AF25: HVZ | AG25: =INDEX('Brown tagset'!$B:$B,MATCH(IF(ISERROR(FIND("-",AF25)),IF(ISERROR(FIND("+",AF25)),AF25,LEFT(AF25,FIND("+",AF25)-1)),LEFT(AF25,FIND("-",AF25)-1)),'Brown tagset'!$A:$A,0)) -> has | AH25: X | AI25: =INDEX('Brown-Universal mapping'!$B:$B,MATCH(AF25,'Brown-Universal mapping'!$A:$A,0)) -> VERB | AJ25: =IF(AF25=$D25,1,0) -> 1 | AK25: =IF(AI25=$G25,1,0) -> 1 | AM25: =M25+AC25+AJ25 -> 3 | AN25: =N25+AD25+AK25 -> 3 | AP25: =AG25&AM25 -> has3
A26: to | D26: TO | E26: =INDEX('Brown tagset'!$B:$B,MATCH(IF(ISERROR(FIND("-",D26)),IF(ISERROR(FIND("+",D26)),D26,LEFT(D26,FIND("+",D26)-1)),LEFT(D26,FIND("-",D26)-1)),'Brown tagset'!$A:$A,0)) -> infinitive marker to | G26: =INDEX('Brown-Universal mapping'!$B:$B,MATCH(D26,'Brown-Universal mapping'!$A:$A,0)) -> PRT | I26: TO | J26: =INDEX('Brown tagset'!$B:$B,MATCH(IF(ISERROR(FIND("-",I26)),IF(ISERROR(FIND("+",I26)),I26,LEFT(I26,FIND("+",I26)-1)),LEFT(I26,FIND("-",I26)-1)),'Brown tagset'!$A:$A,0)) -> infinitive marker to | K26: PRT | L26: =INDEX('Brown-Universal mapping'!$B:$B,MATCH(I26,'Brown-Universal mapping'!$A:$A,0)) -> PRT | M26: =IF(I26=$D26,1,0) -> 1 | N26: =IF(L26=$G26,1,0) -> 1 | P26: to | Q26: to | R26: =INDEX('Brown tagset'!$B:$B,MATCH(IF(ISERROR(FIND("-",Q26)),IF(ISERROR(FIND("+",Q26)),Q26,LEFT(Q26,FIND("+",Q26)-1)),LEFT(Q26,FIND("-",Q26)-1)),'Brown tagset'!$A:$A,0)) -> infinitive marker to | T26: =INDEX('Brown-Universal mapping'!$B:$B,MATCH(Q26,'Brown-Universal mapping'!$A:$A,0)) -> PRT | U26: =IF(Q26=$D26,1,0) -> 1 | V26: =IF(T26=$G26,1,0) -> 1 | X26: to | Y26: to | Z26: =INDEX('Brown tagset'!$B:$B,MATCH(IF(ISERROR(FIND("-",Y26)),IF(ISERROR(FIND("+",Y26)),Y26,LEFT(Y26,FIND("+",Y26)-1)),LEFT(Y26,FIND("-",Y26)-1)),'Brown tagset'!$A:$A,0)) -> infinitive marker to | AB26: =INDEX('Brown-Universal mapping'!$B:$B,MATCH(Y26,'Brown-Universal mapping'!$A:$A,0)) -> PRT | AC26: =IF(Y26=$D26,1,0) -> 1 | AD26: =IF(AB26=$G26,1,0) -> 1 | AF26: TO | AG26: =INDEX('Brown tagset'!$B:$B,MATCH(IF(ISERROR(FIND("-",AF26)),IF(ISERROR(FIND("+",AF26)),AF26,LEFT(AF26,FIND("+",AF26)-1)),LEFT(AF26,FIND("-",AF26)-1)),'Brown tagset'!$A:$A,0)) -> infinitive marker to | AH26: PRT | AI26: =INDEX('Brown-Universal mapping'!$B:$B,MATCH(AF26,'Brown-Universal mapping'!$A:$A,0)) -> PRT | AJ26: =IF(AF26=$D26,1,0) -> 1 | AK26: =IF(AI26=$G26,1,0) -> 1 | AM26: =M26+AC26+AJ26 -> 3 | AN26: =N26+AD26+AK26 -> 3 | AP26: =AG26&AM26 -> infinitive marker to3
A27: do | D27: DO | E27: =INDEX('Brown tagset'!$B:$B,MATCH(IF(ISERROR(FIND("-",D27)),IF(ISERROR(FIND("+",D27)),D27,LEFT(D27,FIND("+",D27)-1)),LEFT(D27,FIND("-",D27)-1)),'Brown tagset'!$A:$A,0)) -> do | G27: =INDEX('Brown-Universal mapping'!$B:$B,MATCH(D27,'Brown-Universal mapping'!$A:$A,0)) -> VERB | I27: DO | J27: =INDEX('Brown tagset'!$B:$B,MATCH(IF(ISERROR(FIND("-",I27)),IF(ISERROR(FIND("+",I27)),I27,LEFT(I27,FIND("+",I27)-1)),LEFT(I27,FIND("-",I27)-1)),'Brown tagset'!$A:$A,0)) -> do | K27: X | L27: =INDEX('Brown-Universal mapping'!$B:$B,MATCH(I27,'Brown-Universal mapping'!$A:$A,0)) -> VERB | M27: =IF(I27=$D27,1,0) -> 1 | N27: =IF(L27=$G27,1,0) -> 1 | P27: do | Q27: do | R27: =INDEX('Brown tagset'!$B:$B,MATCH(IF(ISERROR(FIND("-",Q27)),IF(ISERROR(FIND("+",Q27)),Q27,LEFT(Q27,FIND("+",Q27)-1)),LEFT(Q27,FIND("-",Q27)-1)),'Brown tagset'!$A:$A,0)) -> do | T27: =INDEX('Brown-Universal mapping'!$B:$B,MATCH(Q27,'Brown-Universal mapping'!$A:$A,0)) -> VERB | U27: =IF(Q27=$D27,1,0) -> 1 | V27: =IF(T27=$G27,1,0) -> 1 | X27: do | Y27: do | Z27: =INDEX('Brown tagset'!$B:$B,MATCH(IF(ISERROR(FIND("-",Y27)),IF(ISERROR(FIND("+",Y27)),Y27,LEFT(Y27,FIND("+",Y27)-1)),LEFT(Y27,FIND("-",Y27)-1)),'Brown tagset'!$A:$A,0)) -> do | AB27: =INDEX('Brown-Universal mapping'!$B:$B,MATCH(Y27,'Brown-Universal mapping'!$A:$A,0)) -> VERB | AC27: =IF(Y27=$D27,1,0) -> 1 | AD27: =IF(AB27=$G27,1,0) -> 1 | AF27: DO | AG27: =INDEX('Brown tagset'!$B:$B,MATCH(IF(ISERROR(FIND("-",AF27)),IF(ISERROR(FIND("+",AF27)),AF27,LEFT(AF27,FIND("+",AF27)-1)),LEFT(AF27,FIND("-",AF27)-1)),'Brown tagset'!$A:$A,0)) -> do | AH27: X | AI27: =INDEX('Brown-Universal mapping'!$B:$B,MATCH(AF27,'Brown-Universal mapping'!$A:$A,0)) -> VERB | AJ27: =IF(AF27=$D27,1,0) -> 1 | AK27: =IF(AI27=$G27,1,0) -> 1 | AM27: =M27+AC27+AJ27 -> 3 | AN27: =N27+AD27+AK27 -> 3 | AP27: =AG27&AM27 -> do3
A28: his | D28: PP$ | E28: =INDEX('Brown tagset'!$B:$B,MATCH(IF(ISERROR(FIND("-",D28)),IF(ISERROR(FIND("+",D28)),D28,LEFT(D28,FIND("+",D28)-1)),LEFT(D28,FIND("-",D28)-1)),'Brown tagset'!$A:$A,0)) -> possessive personal pronoun (my, our) | G28: =INDEX('Brown-Universal mapping'!$B:$B,MATCH(D28,'Brown-Universal mapping'!$A:$A,0)) -> DET | I28: PP$ | J28: =INDEX('Brown tagset'!$B:$B,MATCH(IF(ISERROR(FIND("-",I28)),IF(ISERROR(FIND("+",I28)),I28,LEFT(I28,FIND("+",I28)-1)),LEFT(I28,FIND("-",I28)-1)),'Brown tagset'!$A:$A,0)) -> possessive personal pronoun (my, our) | K28: X | L28: =INDEX('Brown-Universal mapping'!$B:$B,MATCH(I28,'Brown-Universal mapping'!$A:$A,0)) -> DET | M28: =IF(I28=$D28,1,0) -> 1 | N28: =IF(L28=$G28,1,0) -> 1 | P28: his | Q28: pp$ | R28: =INDEX('Brown tagset'!$B:$B,MATCH(IF(ISERROR(FIND("-",Q28)),IF(ISERROR(FIND("+",Q28)),Q28,LEFT(Q28,FIND("+",Q28)-1)),LEFT(Q28,FIND("-",Q28)-1)),'Brown tagset'!$A:$A,0)) -> possessive personal pronoun (my, our) | T28: =INDEX('Brown-Universal mapping'!$B:$B,MATCH(Q28,'Brown-Universal mapping'!$A:$A,0)) -> DET | U28: =IF(Q28=$D28,1,0) -> 1 | V28: =IF(T28=$G28,1,0) -> 1 | X28: his | Y28: pp$ | Z28: =INDEX('Brown tagset'!$B:$B,MATCH(IF(ISERROR(FIND("-",Y28)),IF(ISERROR(FIND("+",Y28)),Y28,LEFT(Y28,FIND("+",Y28)-1)),LEFT(Y28,FIND("-",Y28)-1)),'Brown tagset'!$A:$A,0)) -> possessive personal pronoun (my, our) | AB28: =INDEX('Brown-Universal mapping'!$B:$B,MATCH(Y28,'Brown-Universal mapping'!$A:$A,0)) -> DET | AC28: =IF(Y28=$D28,1,0) -> 1 | AD28: =IF(AB28=$G28,1,0) -> 1 | AF28: PP$ | AG28: =INDEX('Brown tagset'!$B:$B,MATCH(IF(ISERROR(FIND("-",AF28)),IF(ISERROR(FIND("+",AF28)),AF28,LEFT(AF28,FIND("+",AF28)-1)),LEFT(AF28,FIND("-",AF28)-1)),'Brown tagset'!$A:$A,0)) -> possessive personal pronoun (my, our) | AH28: X | AI28: =INDEX('Brown-Universal mapping'!$B:$B,MATCH(AF28,'Brown-Universal mapping'!$A:$A,0)) -> DET | AJ28: =IF(AF28=$D28,1,0) -> 1 | AK28: =IF(AI28=$G28,1,0) -> 1 | AM28: =M28+AC28+AJ28 -> 3 | AN28: =N28+AD28+AK28 -> 3 | AP28: =AG28&AM28 -> possessive personal pronoun (my, our)3
A29: training | D29: NN | E29: =INDEX('Brown tagset'!$B:$B,MATCH(IF(ISERROR(FIND("-",D29)),IF(ISERROR(FIND("+",D29)),D29,LEFT(D29,FIND("+",D29)-1)),LEFT(D29,FIND("-",D29)-1)),'Brown tagset'!$A:$A,0)) -> singular or mass noun | G29: =INDEX('Brown-Universal mapping'!$B:$B,MATCH(D29,'Brown-Universal mapping'!$A:$A,0)) -> NOUN | I29: VBG | J29: =INDEX('Brown tagset'!$B:$B,MATCH(IF(ISERROR(FIND("-",I29)),IF(ISERROR(FIND("+",I29)),I29,LEFT(I29,FIND("+",I29)-1)),LEFT(I29,FIND("-",I29)-1)),'Brown tagset'!$A:$A,0)) -> verb, present participle/gerund | K29: VERB | L29: =INDEX('Brown-Universal mapping'!$B:$B,MATCH(I29,'Brown-Universal mapping'!$A:$A,0)) -> VERB | M29: =IF(I29=$D29,1,0) -> 0 | N29: =IF(L29=$G29,1,0) -> 0 | P29: training | Q29: vbg | R29: =INDEX('Brown tagset'!$B:$B,MATCH(IF(ISERROR(FIND("-",Q29)),IF(ISERROR(FIND("+",Q29)),Q29,LEFT(Q29,FIND("+",Q29)-1)),LEFT(Q29,FIND("-",Q29)-1)),'Brown tagset'!$A:$A,0)) -> verb, present participle/gerund | T29: =INDEX('Brown-Universal mapping'!$B:$B,MATCH(Q29,'Brown-Universal mapping'!$A:$A,0)) -> VERB | U29: =IF(Q29=$D29,1,0) -> 0 | V29: =IF(T29=$G29,1,0) -> 0 | X29: training | Y29: nn | Z29: =INDEX('Brown tagset'!$B:$B,MATCH(IF(ISERROR(FIND("-",Y29)),IF(ISERROR(FIND("+",Y29)),Y29,LEFT(Y29,FIND("+",Y29)-1)),LEFT(Y29,FIND("-",Y29)-1)),'Brown tagset'!$A:$A,0)) -> singular or mass noun | AB29: =INDEX('Brown-Universal mapping'!$B:$B,MATCH(Y29,'Brown-Universal mapping'!$A:$A,0)) -> NOUN | AC29: =IF(Y29=$D29,1,0) -> 1 | AD29: =IF(AB29=$G29,1,0) -> 1 | AF29: VBG | AG29: =INDEX('Brown tagset'!$B:$B,MATCH(IF(ISERROR(FIND("-",AF29)),IF(ISERROR(FIND("+",AF29)),AF29,LEFT(AF29,FIND("+",AF29)-1)),LEFT(AF29,FIND("-",AF29)-1)),'Brown tagset'!$A:$A,0)) -> verb, present participle/gerund | AH29: VERB | AI29: =INDEX('Brown-Universal mapping'!$B:$B,MATCH(AF29,'Brown-Universal mapping'!$A:$A,0)) -> VERB | AJ29: =IF(AF29=$D29,1,0) -> 0 | AK29: =IF(AI29=$G29,1,0) -> 0 | AM29: =M29+AC29+AJ29 -> 1 | AN29: =N29+AD29+AK29 -> 1 | AP29: =AG29&AM29 -> verb, present participle/gerund1
A30: secretly | C30: 1 | D30: RB | E30: =INDEX('Brown tagset'!$B:$B,MATCH(IF(ISERROR(FIND("-",D30)),IF(ISERROR(FIND("+",D30)),D30,LEFT(D30,FIND("+",D30)-1)),LEFT(D30,FIND("-",D30)-1)),'Brown tagset'!$A:$A,0)) -> adverb | G30: =INDEX('Brown-Universal mapping'!$B:$B,MATCH(D30,'Brown-Universal mapping'!$A:$A,0)) -> ADV | I30: RB | J30: =INDEX('Brown tagset'!$B:$B,MATCH(IF(ISERROR(FIND("-",I30)),IF(ISERROR(FIND("+",I30)),I30,LEFT(I30,FIND("+",I30)-1)),LEFT(I30,FIND("-",I30)-1)),'Brown tagset'!$A:$A,0)) -> adverb | K30: ADV | L30: =INDEX('Brown-Universal mapping'!$B:$B,MATCH(I30,'Brown-Universal mapping'!$A:$A,0)) -> ADV | M30: =IF(I30=$D30,1,0) -> 1 | N30: =IF(L30=$G30,1,0) -> 1 | P30: secretly | Q30: rb | R30: =INDEX('Brown tagset'!$B:$B,MATCH(IF(ISERROR(FIND("-",Q30)),IF(ISERROR(FIND("+",Q30)),Q30,LEFT(Q30,FIND("+",Q30)-1)),LEFT(Q30,FIND("-",Q30)-1)),'Brown tagset'!$A:$A,0)) -> adverb | T30: =INDEX('Brown-Universal mapping'!$B:$B,MATCH(Q30,'Brown-Universal mapping'!$A:$A,0)) -> ADV | U30: =IF(Q30=$D30,1,0) -> 1 | V30: =IF(T30=$G30,1,0) -> 1 | X30: secretly | Y30: rb | Z30: =INDEX('Brown tagset'!$B:$B,MATCH(IF(ISERROR(FIND("-",Y30)),IF(ISERROR(FIND("+",Y30)),Y30,LEFT(Y30,FIND("+",Y30)-1)),LEFT(Y30,FIND("-",Y30)-1)),'Brown tagset'!$A:$A,0)) -> adverb | AB30: =INDEX('Brown-Universal mapping'!$B:$B,MATCH(Y30,'Brown-Universal mapping'!$A:$A,0)) -> ADV | AC30: =IF(Y30=$D30,1,0) -> 1 | AD30: =IF(AB30=$G30,1,0) -> 1 | AF30: RB | AG30: =INDEX('Brown tagset'!$B:$B,MATCH(IF(ISERROR(FIND("-",AF30)),IF(ISERROR(FIND("+",AF30)),AF30,LEFT(AF30,FIND("+",AF30)-1)),LEFT(AF30,FIND("-",AF30)-1)),'Brown tagset'!$A:$A,0)) -> adverb | AH30: ADV | AI30: =INDEX('Brown-Universal mapping'!$B:$B,MATCH(AF30,'Brown-Universal mapping'!$A:$A,0)) -> ADV | AJ30: =IF(AF30=$D30,1,0) -> 1 | AK30: =IF(AI30=$G30,1,0) -> 1 | AM30: =M30+AC30+AJ30 -> 3 | AN30: =N30+AD30+AK30 -> 3 | AP30: =AG30&AM30 -> adverb3
A31: either | D31: CC | E31: =INDEX('Brown tagset'!$B:$B,MATCH(IF(ISERROR(FIND("-",D31)),IF(ISERROR(FIND("+",D31)),D31,LEFT(D31,FIND("+",D31)-1)),LEFT(D31,FIND("-",D31)-1)),'Brown tagset'!$A:$A,0)) -> coordinating conjunction (and, or) | G31: =INDEX('Brown-Universal mapping'!$B:$B,MATCH(D31,'Brown-Universal mapping'!$A:$A,0)) -> CONJ | I31: CC | J31: =INDEX('Brown tagset'!$B:$B,MATCH(IF(ISERROR(FIND("-",I31)),IF(ISERROR(FIND("+",I31)),I31,LEFT(I31,FIND("+",I31)-1)),LEFT(I31,FIND("-",I31)-1)),'Brown tagset'!$A:$A,0)) -> coordinating conjunction (and, or) | K31: CONJ | L31: =INDEX('Brown-Universal mapping'!$B:$B,MATCH(I31,'Brown-Universal mapping'!$A:$A,0)) -> CONJ | M31: =IF(I31=$D31,1,0) -> 1 | N31: =IF(L31=$G31,1,0) -> 1 | P31: either | Q31: cc | R31: =INDEX('Brown tagset'!$B:$B,MATCH(IF(ISERROR(FIND("-",Q31)),IF(ISERROR(FIND("+",Q31)),Q31,LEFT(Q31,FIND("+",Q31)-1)),LEFT(Q31,FIND("-",Q31)-1)),'Brown tagset'!$A:$A,0)) -> coordinating conjunction (and, or) | T31: =INDEX('Brown-Universal mapping'!$B:$B,MATCH(Q31,'Brown-Universal mapping'!$A:$A,0)) -> CONJ | U31: =IF(Q31=$D31,1,0) -> 1 | V31: =IF(T31=$G31,1,0) -> 1 | X31: either | Y31: cc | Z31: =INDEX('Brown tagset'!$B:$B,MATCH(IF(ISERROR(FIND("-",Y31)),IF(ISERROR(FIND("+",Y31)),Y31,LEFT(Y31,FIND("+",Y31)-1)),LEFT(Y31,FIND("-",Y31)-1)),'Brown tagset'!$A:$A,0)) -> coordinating conjunction (and, or) | AB31: =INDEX('Brown-Universal mapping'!$B:$B,MATCH(Y31,'Brown-Universal mapping'!$A:$A,0)) -> CONJ | AC31: =IF(Y31=$D31,1,0) -> 1 | AD31: =IF(AB31=$G31,1,0) -> 1 | AF31: CC | AG31: =INDEX('Brown tagset'!$B:$B,MATCH(IF(ISERROR(FIND("-",AF31)),IF(ISERROR(FIND("+",AF31)),AF31,LEFT(AF31,FIND("+",AF31)-1)),LEFT(AF31,FIND("-",AF31)-1)),'Brown tagset'!$A:$A,0)) -> coordinating conjunction (and, or) | AH31: CONJ | AI31: =INDEX('Brown-Universal mapping'!$B:$B,MATCH(AF31,'Brown-Universal mapping'!$A:$A,0)) -> CONJ | AJ31: =IF(AF31=$D31,1,0) -> 1 | AK31: =IF(AI31=$G31,1,0) -> 1 | AM31: =M31+AC31+AJ31 -> 3 | AN31: =N31+AD31+AK31 -> 3 | AP31: =AG31&AM31 -> coordinating conjunction (and, or)3
A32: because | D32: CS | E32: =INDEX('Brown tagset'!$B:$B,MATCH(IF(ISERROR(FIND("-",D32)),IF(ISERROR(FIND("+",D32)),D32,LEFT(D32,FIND("+",D32)-1)),LEFT(D32,FIND("-",D32)-1)),'Brown tagset'!$A:$A,0)) -> subordinating conjunction (if, although) | G32: =INDEX('Brown-Universal mapping'!$B:$B,MATCH(D32,'Brown-Universal mapping'!$A:$A,0)) -> ADP | I32: CS | J32: =INDEX('Brown tagset'!$B:$B,MATCH(IF(ISERROR(FIND("-",I32)),IF(ISERROR(FIND("+",I32)),I32,LEFT(I32,FIND("+",I32)-1)),LEFT(I32,FIND("-",I32)-1)),'Brown tagset'!$A:$A,0)) -> subordinating conjunction (if, although) | K32: X | L32: =INDEX('Brown-Universal mapping'!$B:$B,MATCH(I32,'Brown-Universal mapping'!$A:$A,0)) -> ADP | M32: =IF(I32=$D32,1,0) -> 1 | N32: =IF(L32=$G32,1,0) -> 1 | P32: because | Q32: cs | R32: =INDEX('Brown tagset'!$B:$B,MATCH(IF(ISERROR(FIND("-",Q32)),IF(ISERROR(FIND("+",Q32)),Q32,LEFT(Q32,FIND("+",Q32)-1)),LEFT(Q32,FIND("-",Q32)-1)),'Brown tagset'!$A:$A,0)) -> subordinating conjunction (if, although) | T32: =INDEX('Brown-Universal mapping'!$B:$B,MATCH(Q32,'Brown-Universal mapping'!$A:$A,0)) -> ADP | U32: =IF(Q32=$D32,1,0) -> 1 | V32: =IF(T32=$G32,1,0) -> 1 | X32: because | Y32: cs | Z32: =INDEX('Brown tagset'!$B:$B,MATCH(IF(ISERROR(FIND("-",Y32)),IF(ISERROR(FIND("+",Y32)),Y32,LEFT(Y32,FIND("+",Y32)-1)),LEFT(Y32,FIND("-",Y32)-1)),'Brown tagset'!$A:$A,0)) -> subordinating conjunction (if, although) | AB32: =INDEX('Brown-Universal mapping'!$B:$B,MATCH(Y32,'Brown-Universal mapping'!$A:$A,0)) -> ADP | AC32: =IF(Y32=$D32,1,0) -> 1 | AD32: =IF(AB32=$G32,1,0) -> 1 | AF32: CS | AG32: =INDEX('Brown tagset'!$B:$B,MATCH(IF(ISERROR(FIND("-",AF32)),IF(ISERROR(FIND("+",AF32)),AF32,LEFT(AF32,FIND("+",AF32)-1)),LEFT(AF32,FIND("-",AF32)-1)),'Brown tagset'!$A:$A,0)) -> subordinating conjunction (if, although) | AH32: X | AI32: =INDEX('Brown-Universal mapping'!$B:$B,MATCH(AF32,'Brown-Universal mapping'!$A:$A,0)) -> ADP | AJ32: =IF(AF32=$D32,1,0) -> 1 | AK32: =IF(AI32=$G32,1,0) -> 1 | AM32: =M32+AC32+AJ32 -> 3 | AN32: =N32+AD32+AK32 -> 3 | AP32: =AG32&AM32 -> subordinating conjunction (if, although)3
A33: his | D33: PP$ | E33: =INDEX('Brown tagset'!$B:$B,MATCH(IF(ISERROR(FIND("-",D33)),IF(ISERROR(FIND("+",D33)),D33,LEFT(D33,FIND("+",D33)-1)),LEFT(D33,FIND("-",D33)-1)),'Brown tagset'!$A:$A,0)) -> possessive personal pronoun (my, our) | G33: =INDEX('Brown-Universal mapping'!$B:$B,MATCH(D33,'Brown-Universal mapping'!$A:$A,0)) -> DET | I33: PP$ | J33: =INDEX('Brown tagset'!$B:$B,MATCH(IF(ISERROR(FIND("-",I33)),IF(ISERROR(FIND("+",I33)),I33,LEFT(I33,FIND("+",I33)-1)),LEFT(I33,FIND("-",I33)-1)),'Brown tagset'!$A:$A,0)) -> possessive personal pronoun (my, our) | K33: X | L33: =INDEX('Brown-Universal mapping'!$B:$B,MATCH(I33,'Brown-Universal mapping'!$A:$A,0)) -> DET | M33: =IF(I33=$D33,1,0) -> 1 | N33: =IF(L33=$G33,1,0) -> 1 | P33: his | Q33: pp$ | R33: =INDEX('Brown tagset'!$B:$B,MATCH(IF(ISERROR(FIND("-",Q33)),IF(ISERROR(FIND("+",Q33)),Q33,LEFT(Q33,FIND("+",Q33)-1)),LEFT(Q33,FIND("-",Q33)-1)),'Brown tagset'!$A:$A,0)) -> possessive personal pronoun (my, our) | T33: =INDEX('Brown-Universal mapping'!$B:$B,MATCH(Q33,'Brown-Universal mapping'!$A:$A,0)) -> DET | U33: =IF(Q33=$D33,1,0) -> 1 | V33: =IF(T33=$G33,1,0) -> 1 | X33: his | Y33: pp$ | Z33: =INDEX('Brown tagset'!$B:$B,MATCH(IF(ISERROR(FIND("-",Y33)),IF(ISERROR(FIND("+",Y33)),Y33,LEFT(Y33,FIND("+",Y33)-1)),LEFT(Y33,FIND("-",Y33)-1)),'Brown tagset'!$A:$A,0)) -> possessive personal pronoun (my, our) | AB33: =INDEX('Brown-Universal mapping'!$B:$B,MATCH(Y33,'Brown-Universal mapping'!$A:$A,0)) -> DET | AC33: =IF(Y33=$D33,1,0) -> 1 | AD33: =IF(AB33=$G33,1,0) -> 1 | AF33: PP$ | AG33: =INDEX('Brown tagset'!$B:$B,MATCH(IF(ISERROR(FIND("-",AF33)),IF(ISERROR(FIND("+",AF33)),AF33,LEFT(AF33,FIND("+",AF33)-1)),LEFT(AF33,FIND("-",AF33)-1)),'Brown tagset'!$A:$A,0)) -> possessive personal pronoun (my, our) | AH33: X | AI33: =INDEX('Brown-Universal mapping'!$B:$B,MATCH(AF33,'Brown-Universal mapping'!$A:$A,0)) -> DET | AJ33: =IF(AF33=$D33,1,0) -> 1 | AK33: =IF(AI33=$G33,1,0) -> 1 | AM33: =M33+AC33+AJ33 -> 3 | AN33: =N33+AD33+AK33 -> 3 | AP33: =AG33&AM33 -> possessive personal pronoun (my, our)3
A34: parents | D34: NNS | E34: =INDEX('Brown tagset'!$B:$B,MATCH(IF(ISERROR(FIND("-",D34)),IF(ISERROR(FIND("+",D34)),D34,LEFT(D34,FIND("+",D34)-1)),LEFT(D34,FIND("-",D34)-1)),'Brown tagset'!$A:$A,0)) -> plural noun | G34: =INDEX('Brown-Universal mapping'!$B:$B,MATCH(D34,'Brown-Universal mapping'!$A:$A,0)) -> NOUN | I34: NNS | J34: =INDEX('Brown tagset'!$B:$B,MATCH(IF(ISERROR(FIND("-",I34)),IF(ISERROR(FIND("+",I34)),I34,LEFT(I34,FIND("+",I34)-1)),LEFT(I34,FIND("-",I34)-1)),'Brown tagset'!$A:$A,0)) -> plural noun | K34: NOUN | L34: =INDEX('Brown-Universal mapping'!$B:$B,MATCH(I34,'Brown-Universal mapping'!$A:$A,0)) -> NOUN | M34: =IF(I34=$D34,1,0) -> 1 | N34: =IF(L34=$G34,1,0) -> 1 | P34: parents | Q34: nns | R34: =INDEX('Brown tagset'!$B:$B,MATCH(IF(ISERROR(FIND("-",Q34)),IF(ISERROR(FIND("+",Q34)),Q34,LEFT(Q34,FIND("+",Q34)-1)),LEFT(Q34,FIND("-",Q34)-1)),'Brown tagset'!$A:$A,0)) -> plural noun | T34: =INDEX('Brown-Universal mapping'!$B:$B,MATCH(Q34,'Brown-Universal mapping'!$A:$A,0)) -> NOUN | U34: =IF(Q34=$D34,1,0) -> 1 | V34: =IF(T34=$G34,1,0) -> 1 | X34: parents | Y34: nns | Z34: =INDEX('Brown tagset'!$B:$B,MATCH(IF(ISERROR(FIND("-",Y34)),IF(ISERROR(FIND("+",Y34)),Y34,LEFT(Y34,FIND("+",Y34)-1)),LEFT(Y34,FIND("-",Y34)-1)),'Brown tagset'!$A:$A,0)) -> plural noun | AB34: =INDEX('Brown-Universal mapping'!$B:$B,MATCH(Y34,'Brown-Universal mapping'!$A:$A,0)) -> NOUN | AC34: =IF(Y34=$D34,1,0) -> 1 | AD34: =IF(AB34=$G34,1,0) -> 1 | AF34: NNS | AG34: =INDEX('Brown tagset'!$B:$B,MATCH(IF(ISERROR(FIND("-",AF34)),IF(ISERROR(FIND("+",AF34)),AF34,LEFT(AF34,FIND("+",AF34)-1)),LEFT(AF34,FIND("-",AF34)-1)),'Brown tagset'!$A:$A,0)) -> plural noun | AH34: NOUN | AI34: =INDEX('Brown-Universal mapping'!$B:$B,MATCH(AF34,'Brown-Universal mapping'!$A:$A,0)) -> NOUN | AJ34: =IF(AF34=$D34,1,0) -> 1 | AK34: =IF(AI34=$G34,1,0) -> 1 | AM34: =M34+AC34+AJ34 -> 3 | AN34: =N34+AD34+AK34 -> 3 | AP34: =AG34&AM34 -> plural noun3
A35: don't | D35: DO* | E35: =INDEX('Brown tagset'!$B:$B,MATCH(IF(ISERROR(FIND("-",D35)),IF(ISERROR(FIND("+",D35)),D35,LEFT(D35,FIND("+",D35)-1)),LEFT(D35,FIND("-",D35)-1)),'Brown tagset'!$A:$A,0)) -> do | G35: =INDEX('Brown-Universal mapping'!$B:$B,MATCH(D35,'Brown-Universal mapping'!$A:$A,0)) -> VERB | I35: DO* | J35: =INDEX('Brown tagset'!$B:$B,MATCH(IF(ISERROR(FIND("-",I35)),IF(ISERROR(FIND("+",I35)),I35,LEFT(I35,FIND("+",I35)-1)),LEFT(I35,FIND("-",I35)-1)),'Brown tagset'!$A:$A,0)) -> do | K35: X | L35: =INDEX('Brown-Universal mapping'!$B:$B,MATCH(I35,'Brown-Universal mapping'!$A:$A,0)) -> VERB | M35: =IF(I35=$D35,1,0) -> 1 | N35: =IF(L35=$G35,1,0) -> 1 | P35: do | Q35: do | R35: =INDEX('Brown tagset'!$B:$B,MATCH(IF(ISERROR(FIND("-",Q35)),IF(ISERROR(FIND("+",Q35)),Q35,LEFT(Q35,FIND("+",Q35)-1)),LEFT(Q35,FIND("-",Q35)-1)),'Brown tagset'!$A:$A,0)) -> do | T35: =INDEX('Brown-Universal mapping'!$B:$B,MATCH(Q35,'Brown-Universal mapping'!$A:$A,0)) -> VERB | U35: =IF(Q35=$D35,1,0) -> 0 | V35: =IF(T35=$G35,1,0) -> 1 | X35: don't | Y35: do* | Z35: =INDEX('Brown tagset'!$B:$B,MATCH(IF(ISERROR(FIND("-",Y35)),IF(ISERROR(FIND("+",Y35)),Y35,LEFT(Y35,FIND("+",Y35)-1)),LEFT(Y35,FIND("-",Y35)-1)),'Brown tagset'!$A:$A,0)) -> do | AB35: =INDEX('Brown-Universal mapping'!$B:$B,MATCH(Y35,'Brown-Universal mapping'!$A:$A,0)) -> VERB | AC35: =IF(Y35=$D35,1,0) -> 1 | AD35: =IF(AB35=$G35,1,0) -> 1 | AF35: DO* | AG35: =INDEX('Brown tagset'!$B:$B,MATCH(IF(ISERROR(FIND("-",AF35)),IF(ISERROR(FIND("+",AF35)),AF35,LEFT(AF35,FIND("+",AF35)-1)),LEFT(AF35,FIND("-",AF35)-1)),'Brown tagset'!$A:$A,0)) -> do | AH35: X | AI35: =INDEX('Brown-Universal mapping'!$B:$B,MATCH(AF35,'Brown-Universal mapping'!$A:$A,0)) -> VERB | AJ35: =IF(AF35=$D35,1,0) -> 1 | AK35: =IF(AI35=$G35,1,0) -> 1 | AM35: =M35+AC35+AJ35 -> 3 | AN35: =N35+AD35+AK35 -> 3 | AP35: =AG35&AM35 -> do3
A36: want | D36: VB | E36: =INDEX('Brown tagset'!$B:$B,MATCH(IF(ISERROR(FIND("-",D36)),IF(ISERROR(FIND("+",D36)),D36,LEFT(D36,FIND("+",D36)-1)),LEFT(D36,FIND("-",D36)-1)),'Brown tagset'!$A:$A,0)) -> verb, base form | G36: =INDEX('Brown-Universal mapping'!$B:$B,MATCH(D36,'Brown-Universal mapping'!$A:$A,0)) -> VERB | I36: VB | J36: =INDEX('Brown tagset'!$B:$B,MATCH(IF(ISERROR(FIND("-",I36)),IF(ISERROR(FIND("+",I36)),I36,LEFT(I36,FIND("+",I36)-1)),LEFT(I36,FIND("-",I36)-1)),'Brown tagset'!$A:$A,0)) -> verb, base form | K36: VERB | L36: =INDEX('Brown-Universal mapping'!$B:$B,MATCH(I36,'Brown-Universal mapping'!$A:$A,0)) -> VERB | M36: =IF(I36=$D36,1,0) -> 1 | N36: =IF(L36=$G36,1,0) -> 1 | P36: want | Q36: vb | R36: =INDEX('Brown tagset'!$B:$B,MATCH(IF(ISERROR(FIND("-",Q36)),IF(ISERROR(FIND("+",Q36)),Q36,LEFT(Q36,FIND("+",Q36)-1)),LEFT(Q36,FIND("-",Q36)-1)),'Brown tagset'!$A:$A,0)) -> verb, base form | T36: =INDEX('Brown-Universal mapping'!$B:$B,MATCH(Q36,'Brown-Universal mapping'!$A:$A,0)) -> VERB | U36: =IF(Q36=$D36,1,0) -> 1 | V36: =IF(T36=$G36,1,0) -> 1 | X36: want | Y36: vb | Z36: =INDEX('Brown tagset'!$B:$B,MATCH(IF(ISERROR(FIND("-",Y36)),IF(ISERROR(FIND("+",Y36)),Y36,LEFT(Y36,FIND("+",Y36)-1)),LEFT(Y36,FIND("-",Y36)-1)),'Brown tagset'!$A:$A,0)) -> verb, base form | AB36: VERB | AC36: =IF(Y36=$D36,1,0) -> 1 | AD36: =IF(AB36=$G36,1,0) -> 1 | AF36: VB | AG36: =INDEX('Brown tagset'!$B:$B,MATCH(IF(ISERROR(FIND("-",AF36)),IF(ISERROR(FIND("+",AF36)),AF36,LEFT(AF36,FIND("+",AF36)-1)),LEFT(AF36,FIND("-",AF36)-1)),'Brown tagset'!$A:$A,0)) -> verb, base form | AH36: VERB | AI36: =INDEX('Brown-Universal mapping'!$B:$B,MATCH(AF36,'Brown-Universal mapping'!$A:$A,0)) -> VERB | AJ36: =IF(AF36=$D36,1,0) -> 1 | AK36: =IF(AI36=$G36,1,0) -> 1 | AM36: =M36+AC36+AJ36 -> 3 | AN36: =N36+AD36+AK36 -> 3 | AP36: =AG36&AM36 -> verb, base form3
A37: sonny-boy | D37: NN | E37: =INDEX('Brown tagset'!$B:$B,MATCH(IF(ISERROR(FIND("-",D37)),IF(ISERROR(FIND("+",D37)),D37,LEFT(D37,FIND("+",D37)-1)),LEFT(D37,FIND("-",D37)-1)),'Brown tagset'!$A:$A,0)) -> singular or mass noun | G37: =INDEX('Brown-Universal mapping'!$B:$B,MATCH(D37,'Brown-Universal mapping'!$A:$A,0)) -> NOUN | I37: NN | J37: =INDEX('Brown tagset'!$B:$B,MATCH(IF(ISERROR(FIND("-",I37)),IF(ISERROR(FIND("+",I37)),I37,LEFT(I37,FIND("+",I37)-1)),LEFT(I37,FIND("-",I37)-1)),'Brown tagset'!$A:$A,0)) -> singular or mass noun | K37: NOUN | L37: =INDEX('Brown-Universal mapping'!$B:$B,MATCH(I37,'Brown-Universal mapping'!$A:$A,0)) -> NOUN | M37: =IF(I37=$D37,1,0) -> 1 | N37: =IF(L37=$G37,1,0) -> 1 | P37: sonny-boy | Q37: rb | R37: =INDEX('Brown tagset'!$B:$B,MATCH(IF(ISERROR(FIND("-",Q37)),IF(ISERROR(FIND("+",Q37)),Q37,LEFT(Q37,FIND("+",Q37)-1)),LEFT(Q37,FIND("-",Q37)-1)),'Brown tagset'!$A:$A,0)) -> adverb | T37: =INDEX('Brown-Universal mapping'!$B:$B,MATCH(Q37,'Brown-Universal mapping'!$A:$A,0)) -> ADV | U37: =IF(Q37=$D37,1,0) -> 0 | V37: =IF(T37=$G37,1,0) -> 0 | X37: sonny-boy | Y37: jj | Z37: =INDEX('Brown tagset'!$B:$B,MATCH(IF(ISERROR(FIND("-",Y37)),IF(ISERROR(FIND("+",Y37)),Y37,LEFT(Y37,FIND("+",Y37)-1)),LEFT(Y37,FIND("-",Y37)-1)),'Brown tagset'!$A:$A,0)) -> adjective | AB37: =INDEX('Brown-Universal mapping'!$B:$B,MATCH(Y37,'Brown-Universal mapping'!$A:$A,0)) -> ADJ | AC37: =IF(Y37=$D37,1,0) -> 0 | AD37: =IF(AB37=$G37,1,0) -> 0 | AF37: Unk | AG37: =INDEX('Brown tagset'!$B:$B,MATCH(IF(ISERROR(FIND("-",AF37)),IF(ISERROR(FIND("+",AF37)),AF37,LEFT(AF37,FIND("+",AF37)-1)),LEFT(AF37,FIND("-",AF37)-1)),'Brown tagset'!$A:$A,0)) -> unknown | AH37: X | AI37: =INDEX('Brown-Universal mapping'!$B:$B,MATCH(AF37,'Brown-Universal mapping'!$A:$A,0)) -> Unknown | AJ37: =IF(AF37=$D37,1,0) -> 0 | AK37: =IF(AI37=$G37,1,0) -> 0 | AM37: =M37+AC37+AJ37 -> 1 | AN37: =N37+AD37+AK37 -> 1 | AP37: =AG37&AM37 -> unknown1
A38: to | D38: TO | E38: =INDEX('Brown tagset'!$B:$B,MATCH(IF(ISERROR(FIND("-",D38)),IF(ISERROR(FIND("+",D38)),D38,LEFT(D38,FIND("+",D38)-1)),LEFT(D38,FIND("-",D38)-1)),'Brown tagset'!$A:$A,0)) -> infinitive marker to | G38: =INDEX('Brown-Universal mapping'!$B:$B,MATCH(D38,'Brown-Universal mapping'!$A:$A,0)) -> PRT | I38: TO | J38: =INDEX('Brown tagset'!$B:$B,MATCH(IF(ISERROR(FIND("-",I38)),IF(ISERROR(FIND("+",I38)),I38,LEFT(I38,FIND("+",I38)-1)),LEFT(I38,FIND("-",I38)-1)),'Brown tagset'!$A:$A,0)) -> infinitive marker to | K38: PRT | L38: =INDEX('Brown-Universal mapping'!$B:$B,MATCH(I38,'Brown-Universal mapping'!$A:$A,0)) -> PRT | M38: =IF(I38=$D38,1,0) -> 1 | N38: =IF(L38=$G38,1,0) -> 1 | P38: to | Q38: to | R38: =INDEX('Brown tagset'!$B:$B,MATCH(IF(ISERROR(FIND("-",Q38)),IF(ISERROR(FIND("+",Q38)),Q38,LEFT(Q38,FIND("+",Q38)-1)),LEFT(Q38,FIND("-",Q38)-1)),'Brown tagset'!$A:$A,0)) -> infinitive marker to | T38: =INDEX('Brown-Universal mapping'!$B:$B,MATCH(Q38,'Brown-Universal mapping'!$A:$A,0)) -> PRT | U38: =IF(Q38=$D38,1,0) -> 1 | V38: =IF(T38=$G38,1,0) -> 1 | X38: to | Y38: in | Z38: =INDEX('Brown tagset'!$B:$B,MATCH(IF(ISERROR(FIND("-",Y38)),IF(ISERROR(FIND("+",Y38)),Y38,LEFT(Y38,FIND("+",Y38)-1)),LEFT(Y38,FIND("-",Y38)-1)),'Brown tagset'!$A:$A,0)) -> preposition | AB38: =INDEX('Brown-Universal mapping'!$B:$B,MATCH(Y38,'Brown-Universal mapping'!$A:$A,0)) -> ADP | AC38: =IF(Y38=$D38,1,0) -> 0 | AD38: =IF(AB38=$G38,1,0) -> 0 | AF38: TO | AG38: =INDEX('Brown tagset'!$B:$B,MATCH(IF(ISERROR(FIND("-",AF38)),IF(ISERROR(FIND("+",AF38)),AF38,LEFT(AF38,FIND("+",AF38)-1)),LEFT(AF38,FIND("-",AF38)-1)),'Brown tagset'!$A:$A,0)) -> infinitive marker to | AH38: PRT | AI38: =INDEX('Brown-Universal mapping'!$B:$B,MATCH(AF38,'Brown-Universal mapping'!$A:$A,0)) -> PRT | AJ38: =IF(AF38=$D38,1,0) -> 1 | AK38: =IF(AI38=$G38,1,0) -> 1 | AM38: =M38+AC38+AJ38 -> 2 | AN38: =N38+AD38+AK38 -> 2 | AP38: =AG38&AM38 -> infinitive marker to2
A39: `` | D39: `` | E39: =INDEX('Brown tagset'!$B:$B,MATCH(IF(ISERROR(FIND("-",D39)),IF(ISERROR(FIND("+",D39)),D39,LEFT(D39,FIND("+",D39)-1)),LEFT(D39,FIND("-",D39)-1)),'Brown tagset'!$A:$A,0)) -> end quotation | G39: =INDEX('Brown-Universal mapping'!$B:$B,MATCH(D39,'Brown-Universal mapping'!$A:$A,0)) -> . | I39: `` | J39: =INDEX('Brown tagset'!$B:$B,MATCH(IF(ISERROR(FIND("-",I39)),IF(ISERROR(FIND("+",I39)),I39,LEFT(I39,FIND("+",I39)-1)),LEFT(I39,FIND("-",I39)-1)),'Brown tagset'!$A:$A,0)) -> end quotation | K39: . | L39: =INDEX('Brown-Universal mapping'!$B:$B,MATCH(I39,'Brown-Universal mapping'!$A:$A,0)) -> . | M39: =IF(I39=$D39,1,0) -> 1 | N39: =IF(L39=$G39,1,0) -> 1 | P39: `` | Q39: `` | R39: =INDEX('Brown tagset'!$B:$B,MATCH(IF(ISERROR(FIND("-",Q39)),IF(ISERROR(FIND("+",Q39)),Q39,LEFT(Q39,FIND("+",Q39)-1)),LEFT(Q39,FIND("-",Q39)-1)),'Brown tagset'!$A:$A,0)) -> end quotation | T39: =INDEX('Brown-Universal mapping'!$B:$B,MATCH(Q39,'Brown-Universal mapping'!$A:$A,0)) -> . | U39: =IF(Q39=$D39,1,0) -> 1 | V39: =IF(T39=$G39,1,0) -> 1 | X39: `` | Y39: `` | Z39: =INDEX('Brown tagset'!$B:$B,MATCH(IF(ISERROR(FIND("-",Y39)),IF(ISERROR(FIND("+",Y39)),Y39,LEFT(Y39,FIND("+",Y39)-1)),LEFT(Y39,FIND("-",Y39)-1)),'Brown tagset'!$A:$A,0)) -> end quotation | AB39: =INDEX('Brown-Universal mapping'!$B:$B,MATCH(Y39,'Brown-Universal mapping'!$A:$A,0)) -> . | AC39: =IF(Y39=$D39,1,0) -> 1 | AD39: =IF(AB39=$G39,1,0) -> 1 | AF39: `` | AG39: =INDEX('Brown tagset'!$B:$B,MATCH(IF(ISERROR(FIND("-",AF39)),IF(ISERROR(FIND("+",AF39)),AF39,LEFT(AF39,FIND("+",AF39)-1)),LEFT(AF39,FIND("-",AF39)-1)),'Brown tagset'!$A:$A,0)) -> end quotation | AH39: . | AI39: =INDEX('Brown-Universal mapping'!$B:$B,MATCH(AF39,'Brown-Universal mapping'!$A:$A,0)) -> . | AJ39: =IF(AF39=$D39,1,0) -> 1 | AK39: =IF(AI39=$G39,1,0) -> 1 | AM39: =M39+AC39+AJ39 -> 3 | AN39: =N39+AD39+AK39 -> 3 | AP39: =AG39&AM39 -> end quotation3
A40: lift | D40: VB | E40: =INDEX('Brown tagset'!$B:$B,MATCH(IF(ISERROR(FIND("-",D40)),IF(ISERROR(FIND("+",D40)),D40,LEFT(D40,FIND("+",D40)-1)),LEFT(D40,FIND("-",D40)-1)),'Brown tagset'!$A:$A,0)) -> verb, base form | G40: =INDEX('Brown-Universal mapping'!$B:$B,MATCH(D40,'Brown-Universal mapping'!$A:$A,0)) -> VERB | I40: VB | J40: =INDEX('Brown tagset'!$B:$B,MATCH(IF(ISERROR(FIND("-",I40)),IF(ISERROR(FIND("+",I40)),I40,LEFT(I40,FIND("+",I40)-1)),LEFT(I40,FIND("-",I40)-1)),'Brown tagset'!$A:$A,0)) -> verb, base form | K40: VERB | L40: =INDEX('Brown-Universal mapping'!$B:$B,MATCH(I40,'Brown-Universal mapping'!$A:$A,0)) -> VERB | M40: =IF(I40=$D40,1,0) -> 1 | N40: =IF(L40=$G40,1,0) -> 1 | P40: lift | Q40: vb | R40: =INDEX('Brown tagset'!$B:$B,MATCH(IF(ISERROR(FIND("-",Q40)),IF(ISERROR(FIND("+",Q40)),Q40,LEFT(Q40,FIND("+",Q40)-1)),LEFT(Q40,FIND("-",Q40)-1)),'Brown tagset'!$A:$A,0)) -> verb, base form | T40: =INDEX('Brown-Universal mapping'!$B:$B,MATCH(Q40,'Brown-Universal mapping'!$A:$A,0)) -> VERB | U40: =IF(Q40=$D40,1,0) -> 1 | V40: =IF(T40=$G40,1,0) -> 1 | X40: lift | Y40: vb | Z40: =INDEX('Brown tagset'!$B:$B,MATCH(IF(ISERROR(FIND("-",Y40)),IF(ISERROR(FIND("+",Y40)),Y40,LEFT(Y40,FIND("+",Y40)-1)),LEFT(Y40,FIND("-",Y40)-1)),'Brown tagset'!$A:$A,0)) -> verb, base form | AB40: VERB | AC40: =IF(Y40=$D40,1,0) -> 1 | AD40: =IF(AB40=$G40,1,0) -> 1 | AF40: VB | AG40: =INDEX('Brown tagset'!$B:$B,MATCH(IF(ISERROR(FIND("-",AF40)),IF(ISERROR(FIND("+",AF40)),AF40,LEFT(AF40,FIND("+",AF40)-1)),LEFT(AF40,FIND("-",AF40)-1)),'Brown tagset'!$A:$A,0)) -> verb, base form | AH40: VERB | AI40: =INDEX('Brown-Universal mapping'!$B:$B,MATCH(AF40,'Brown-Universal mapping'!$A:$A,0)) -> VERB | AJ40: =IF(AF40=$D40,1,0) -> 1 | AK40: =IF(AI40=$G40,1,0) -> 1 | AM40: =M40+AC40+AJ40 -> 3 | AN40: =N40+AD40+AK40 -> 3 | AP40: =AG40&AM40 -> verb, base form3
A41: all | D41: ABN | E41: =INDEX('Brown tagset'!$B:$B,MATCH(IF(ISERROR(FIND("-",D41)),IF(ISERROR(FIND("+",D41)),D41,LEFT(D41,FIND("+",D41)-1)),LEFT(D41,FIND("-",D41)-1)),'Brown tagset'!$A:$A,0)) -> pre-quantifier (half, all) | G41: =INDEX('Brown-Universal mapping'!$B:$B,MATCH(D41,'Brown-Universal mapping'!$A:$A,0)) -> PRT | I41: ABN | J41: =INDEX('Brown tagset'!$B:$B,MATCH(IF(ISERROR(FIND("-",I41)),IF(ISERROR(FIND("+",I41)),I41,LEFT(I41,FIND("+",I41)-1)),LEFT(I41,FIND("-",I41)-1)),'Brown tagset'!$A:$A,0)) -> pre-quantifier (half, all) | K41: X | L41: =INDEX('Brown-Universal mapping'!$B:$B,MATCH(I41,'Brown-Universal mapping'!$A:$A,0)) -> PRT | M41: =IF(I41=$D41,1,0) -> 1 | N41: =IF(L41=$G41,1,0) -> 1 | P41: all | Q41: abn | R41: =INDEX('Brown tagset'!$B:$B,MATCH(IF(ISERROR(FIND("-",Q41)),IF(ISERROR(FIND("+",Q41)),Q41,LEFT(Q41,FIND("+",Q41)-1)),LEFT(Q41,FIND("-",Q41)-1)),'Brown tagset'!$A:$A,0)) -> pre-quantifier (half, all) | T41: =INDEX('Brown-Universal mapping'!$B:$B,MATCH(Q41,'Brown-Universal mapping'!$A:$A,0)) -> PRT | U41: =IF(Q41=$D41,1,0) -> 1 | V41: =IF(T41=$G41,1,0) -> 1 | X41: all | Y41: abn | Z41: =INDEX('Brown tagset'!$B:$B,MATCH(IF(ISERROR(FIND("-",Y41)),IF(ISERROR(FIND("+",Y41)),Y41,LEFT(Y41,FIND("+",Y41)-1)),LEFT(Y41,FIND("-",Y41)-1)),'Brown tagset'!$A:$A,0)) -> pre-quantifier (half, all) | AB41: =INDEX('Brown-Universal mapping'!$B:$B,MATCH(Y41,'Brown-Universal mapping'!$A:$A,0)) -> PRT | AC41: =IF(Y41=$D41,1,0) -> 1 | AD41: =IF(AB41=$G41,1,0) -> 1 | AF41: ABN | AG41: =INDEX('Brown tagset'!$B:$B,MATCH(IF(ISERROR(FIND("-",AF41)),IF(ISERROR(FIND("+",AF41)),AF41,LEFT(AF41,FIND("+",AF41)-1)),LEFT(AF41,FIND("-",AF41)-1)),'Brown tagset'!$A:$A,0)) -> pre-quantifier (half, all) | AH41: X | AI41: =INDEX('Brown-Universal mapping'!$B:$B,MATCH(AF41,'Brown-Universal mapping'!$A:$A,0)) -> PRT | AJ41: =IF(AF41=$D41,1,0) -> 1 | AK41: =IF(AI41=$G41,1,0) -> 1 | AM41: =M41+AC41+AJ41 -> 3 | AN41: =N41+AD41+AK41 -> 3 | AP41: =AG41&AM41 -> pre-quantifier (half, all)3
A42: those | D42: DTS | E42: =INDEX('Brown tagset'!$B:$B,MATCH(IF(ISERROR(FIND("-",D42)),IF(ISERROR(FIND("+",D42)),D42,LEFT(D42,FIND("+",D42)-1)),LEFT(D42,FIND("-",D42)-1)),'Brown tagset'!$A:$A,0)) -> plural determiner (these, those) | G42: =INDEX('Brown-Universal mapping'!$B:$B,MATCH(D42,'Brown-Universal mapping'!$A:$A,0)) -> DET | I42: DTS | J42: =INDEX('Brown tagset'!$B:$B,MATCH(IF(ISERROR(FIND("-",I42)),IF(ISERROR(FIND("+",I42)),I42,LEFT(I42,FIND("+",I42)-1)),LEFT(I42,FIND("-",I42)-1)),'Brown tagset'!$A:$A,0)) -> plural determiner (these, those) | K42: X | L42: =INDEX('Brown-Universal mapping'!$B:$B,MATCH(I42,'Brown-Universal mapping'!$A:$A,0)) -> DET | M42: =IF(I42=$D42,1,0) -> 1 | N42: =IF(L42=$G42,1,0) -> 1 | P42: those | Q42: dts | R42: =INDEX('Brown tagset'!$B:$B,MATCH(IF(ISERROR(FIND("-",Q42)),IF(ISERROR(FIND("+",Q42)),Q42,LEFT(Q42,FIND("+",Q42)-1)),LEFT(Q42,FIND("-",Q42)-1)),'Brown tagset'!$A:$A,0)) -> plural determiner (these, those) | T42: =INDEX('Brown-Universal mapping'!$B:$B,MATCH(Q42,'Brown-Universal mapping'!$A:$A,0)) -> DET | U42: =IF(Q42=$D42,1,0) -> 1 | V42: =IF(T42=$G42,1,0) -> 1 | X42: those | Y42: dts | Z42: =INDEX('Brown tagset'!$B:$B,MATCH(IF(ISERROR(FIND("-",Y42)),IF(ISERROR(FIND("+",Y42)),Y42,LEFT(Y42,FIND("+",Y42)-1)),LEFT(Y42,FIND("-",Y42)-1)),'Brown tagset'!$A:$A,0)) -> plural determiner (these, those) | AB42: =INDEX('Brown-Universal mapping'!$B:$B,MATCH(Y42,'Brown-Universal mapping'!$A:$A,0)) -> DET | AC42: =IF(Y42=$D42,1,0) -> 1 | AD42: =IF(AB42=$G42,1,0) -> 1 | AF42: DTS | AG42: =INDEX('Brown tagset'!$B:$B,MATCH(IF(ISERROR(FIND("-",AF42)),IF(ISERROR(FIND("+",AF42)),AF42,LEFT(AF42,FIND("+",AF42)-1)),LEFT(AF42,FIND("-",AF42)-1)),'Brown tagset'!$A:$A,0)) -> plural determiner (these, those) | AH42: X | AI42: =INDEX('Brown-Universal mapping'!$B:$B,MATCH(AF42,'Brown-Universal mapping'!$A:$A,0)) -> DET | AJ42: =IF(AF42=$D42,1,0) -> 1 | AK42: =IF(AI42=$G42,1,0) -> 1 | AM42: =M42+AC42+AJ42 -> 3 | AN42: =N42+AD42+AK42 -> 3 | AP42: =AG42&AM42 -> plural determiner (these, those)3
A43: old | D43: JJ | E43: =INDEX('Brown tagset'!$B:$B,MATCH(IF(ISERROR(FIND("-",D43)),IF(ISERROR(FIND("+",D43)),D43,LEFT(D43,FIND("+",D43)-1)),LEFT(D43,FIND("-",D43)-1)),'Brown tagset'!$A:$A,0)) -> adjective | G43: =INDEX('Brown-Universal mapping'!$B:$B,MATCH(D43,'Brown-Universal mapping'!$A:$A,0)) -> ADJ | I43: JJ | J43: =INDEX('Brown tagset'!$B:$B,MATCH(IF(ISERROR(FIND("-",I43)),IF(ISERROR(FIND("+",I43)),I43,LEFT(I43,FIND("+",I43)-1)),LEFT(I43,FIND("-",I43)-1)),'Brown tagset'!$A:$A,0)) -> adjective | K43: ADJ | L43: =INDEX('Brown-Universal mapping'!$B:$B,MATCH(I43,'Brown-Universal mapping'!$A:$A,0)) -> ADJ | M43: =IF(I43=$D43,1,0) -> 1 | N43: =IF(L43=$G43,1,0) -> 1 | P43: old | Q43: jj | R43: =INDEX('Brown tagset'!$B:$B,MATCH(IF(ISERROR(FIND("-",Q43)),IF(ISERROR(FIND("+",Q43)),Q43,LEFT(Q43,FIND("+",Q43)-1)),LEFT(Q43,FIND("-",Q43)-1)),'Brown tagset'!$A:$A,0)) -> adjective | T43: =INDEX('Brown-Universal mapping'!$B:$B,MATCH(Q43,'Brown-Universal mapping'!$A:$A,0)) -> ADJ | U43: =IF(Q43=$D43,1,0) -> 1 | V43: =IF(T43=$G43,1,0) -> 1 | X43: old | Y43: jj | Z43: =INDEX('Brown tagset'!$B:$B,MATCH(IF(ISERROR(FIND("-",Y43)),IF(ISERROR(FIND("+",Y43)),Y43,LEFT(Y43,FIND("+",Y43)-1)),LEFT(Y43,FIND("-",Y43)-1)),'Brown tagset'!$A:$A,0)) -> adjective | AB43: =INDEX('Brown-Universal mapping'!$B:$B,MATCH(Y43,'Brown-Universal mapping'!$A:$A,0)) -> ADJ | AC43: =IF(Y43=$D43,1,0) -> 1 | AD43: =IF(AB43=$G43,1,0) -> 1 | AF43: JJ | AG43: =INDEX('Brown tagset'!$B:$B,MATCH(IF(ISERROR(FIND("-",AF43)),IF(ISERROR(FIND("+",AF43)),AF43,LEFT(AF43,FIND("+",AF43)-1)),LEFT(AF43,FIND("-",AF43)-1)),'Brown tagset'!$A:$A,0)) -> adjective | AH43: ADJ | AI43: =INDEX('Brown-Universal mapping'!$B:$B,MATCH(AF43,'Brown-Universal mapping'!$A:$A,0)) -> ADJ | AJ43: =IF(AF43=$D43,1,0) -> 1 | AK43: =IF(AI43=$G43,1,0) -> 1 | AM43: =M43+AC43+AJ43 -> 3 | AN43: =N43+AD43+AK43 -> 3 | AP43: =AG43&AM43 -> adjective3
A44: barbell | D44: NN | E44: =INDEX('Brown tagset'!$B:$B,MATCH(IF(ISERROR(FIND("-",D44)),IF(ISERROR(FIND("+",D44)),D44,LEFT(D44,FIND("+",D44)-1)),LEFT(D44,FIND("-",D44)-1)),'Brown tagset'!$A:$A,0)) -> singular or mass noun | G44: =INDEX('Brown-Universal mapping'!$B:$B,MATCH(D44,'Brown-Universal mapping'!$A:$A,0)) -> NOUN | I44: JJ | J44: =INDEX('Brown tagset'!$B:$B,MATCH(IF(ISERROR(FIND("-",I44)),IF(ISERROR(FIND("+",I44)),I44,LEFT(I44,FIND("+",I44)-1)),LEFT(I44,FIND("-",I44)-1)),'Brown tagset'!$A:$A,0)) -> adjective | K44: ADJ | L44: =INDEX('Brown-Universal mapping'!$B:$B,MATCH(I44,'Brown-Universal mapping'!$A:$A,0)) -> ADJ | M44: =IF(I44=$D44,1,0) -> 0 | N44: =IF(L44=$G44,1,0) -> 0 | P44: barbell | Q44: nn | R44: =INDEX('Brown tagset'!$B:$B,MATCH(IF(ISERROR(FIND("-",Q44)),IF(ISERROR(FIND("+",Q44)),Q44,LEFT(Q44,FIND("+",Q44)-1)),LEFT(Q44,FIND("-",Q44)-1)),'Brown tagset'!$A:$A,0)) -> singular or mass noun | T44: =INDEX('Brown-Universal mapping'!$B:$B,MATCH(Q44,'Brown-Universal mapping'!$A:$A,0)) -> NOUN | U44: =IF(Q44=$D44,1,0) -> 1 | V44: =IF(T44=$G44,1,0) -> 1 | X44: barbell | Y44: nn | Z44: =INDEX('Brown tagset'!$B:$B,MATCH(IF(ISERROR(FIND("-",Y44)),IF(ISERROR(FIND("+",Y44)),Y44,LEFT(Y44,FIND("+",Y44)-1)),LEFT(Y44,FIND("-",Y44)-1)),'Brown tagset'!$A:$A,0)) -> singular or mass noun | AB44: =INDEX('Brown-Universal mapping'!$B:$B,MATCH(Y44,'Brown-Universal mapping'!$A:$A,0)) -> NOUN | AC44: =IF(Y44=$D44,1,0) -> 1 | AD44: =IF(AB44=$G44,1,0) -> 1 | AF44: Unk | AG44: =INDEX('Brown tagset'!$B:$B,MATCH(IF(ISERROR(FIND("-",AF44)),IF(ISERROR(FIND("+",AF44)),AF44,LEFT(AF44,FIND("+",AF44)-1)),LEFT(AF44,FIND("-",AF44)-1)),'Brown tagset'!$A:$A,0)) -> unknown | AH44: X | AI44: =INDEX('Brown-Universal mapping'!$B:$B,MATCH(AF44,'Brown-Universal mapping'!$A:$A,0)) -> Unknown | AJ44: =IF(AF44=$D44,1,0) -> 0 | AK44: =IF(AI44=$G44,1,0) -> 0 | AM44: =M44+AC44+AJ44 -> 1 | AN44: =N44+AD44+AK44 -> 1 | AP44: =AG44&AM44 -> unknown1
A45: things | D45: NNS | E45: =INDEX('Brown tagset'!$B:$B,MATCH(IF(ISERROR(FIND("-",D45)),IF(ISERROR(FIND("+",D45)),D45,LEFT(D45,FIND("+",D45)-1)),LEFT(D45,FIND("-",D45)-1)),'Brown tagset'!$A:$A,0)) -> plural noun | G45: =INDEX('Brown-Universal mapping'!$B:$B,MATCH(D45,'Brown-Universal mapping'!$A:$A,0)) -> NOUN | I45: NNS | J45: =INDEX('Brown tagset'!$B:$B,MATCH(IF(ISERROR(FIND("-",I45)),IF(ISERROR(FIND("+",I45)),I45,LEFT(I45,FIND("+",I45)-1)),LEFT(I45,FIND("-",I45)-1)),'Brown tagset'!$A:$A,0)) -> plural noun | K45: NOUN | L45: =INDEX('Brown-Universal mapping'!$B:$B,MATCH(I45,'Brown-Universal mapping'!$A:$A,0)) -> NOUN | M45: =IF(I45=$D45,1,0) -> 1 | N45: =IF(L45=$G45,1,0) -> 1 | P45: things | Q45: nns | R45: =INDEX('Brown tagset'!$B:$B,MATCH(IF(ISERROR(FIND("-",Q45)),IF(ISERROR(FIND("+",Q45)),Q45,LEFT(Q45,FIND("+",Q45)-1)),LEFT(Q45,FIND("-",Q45)-1)),'Brown tagset'!$A:$A,0)) -> plural noun | T45: =INDEX('Brown-Universal mapping'!$B:$B,MATCH(Q45,'Brown-Universal mapping'!$A:$A,0)) -> NOUN | U45: =IF(Q45=$D45,1,0) -> 1 | V45: =IF(T45=$G45,1,0) -> 1 | X45: things | Y45: nns | Z45: =INDEX('Brown tagset'!$B:$B,MATCH(IF(ISERROR(FIND("-",Y45)),IF(ISERROR(FIND("+",Y45)),Y45,LEFT(Y45,FIND("+",Y45)-1)),LEFT(Y45,FIND("-",Y45)-1)),'Brown tagset'!$A:$A,0)) -> plural noun | AB45: =INDEX('Brown-Universal mapping'!$B:$B,MATCH(Y45,'Brown-Universal mapping'!$A:$A,0)) -> NOUN | AC45: =IF(Y45=$D45,1,0) -> 1 | AD45: =IF(AB45=$G45,1,0) -> 1 | AF45: NNS | AG45: =INDEX('Brown tagset'!$B:$B,MATCH(IF(ISERROR(FIND("-",AF45)),IF(ISERROR(FIND("+",AF45)),AF45,LEFT(AF45,FIND("+",AF45)-1)),LEFT(AF45,FIND("-",AF45)-1)),'Brown tagset'!$A:$A,0)) -> plural noun | AH45: NOUN | AI45: =INDEX('Brown-Universal mapping'!$B:$B,MATCH(AF45,'Brown-Universal mapping'!$A:$A,0)) -> NOUN | AJ45: =IF(AF45=$D45,1,0) -> 1 | AK45: =IF(AI45=$G45,1,0) -> 1 | AM45: =M45+AC45+AJ45 -> 3 | AN45: =N45+AD45+AK45 -> 3 | AP45: =AG45&AM45 -> plural noun3
...

Sheet gold tagset
A2: Etiquetas gold presentes en el texto analizado ce01
A4: label | B4: En Brown tagset
A5: '' | B5: =MATCH(A5,'Brown tagset'!A:A,0) -> 96
A6: -- | B6: =MATCH(A6,'Brown tagset'!A:A,0) -> 9
A7: ( | B7: =MATCH(A7,'Brown tagset'!A:A,0) -> 6
A8: ) | B8: =MATCH(A8,'Brown tagset'!A:A,0) -> 7
A9: , | B9: =MATCH(A9,'Brown tagset'!A:A,0) -> 10
A10: . | B10: =MATCH(A10,'Brown tagset'!A:A,0) -> 5
A11: `` | B11: =MATCH(A11,'Brown tagset'!A:A,0) -> 97
A12: ABN | B12: =MATCH(A12,'Brown tagset'!A:A,0) -> 13
A13: AP | B13: =MATCH(A13,'Brown tagset'!A:A,0) -> 15
A14: AT | B14: =MATCH(A14,'Brown tagset'!A:A,0) -> 16
A15: BEDZ | B15: =MATCH(A15,'Brown tagset'!A:A,0) -> 19
A16: BEN | B16: =MATCH(A16,'Brown tagset'!A:A,0) -> 22
... A72: WPS | B72: =MATCH(A72,'Brown tagset'!A:A,0) -> 89

Sheet Brown tagset
A2: Brown Tagset [http://clu.uni.no/icame/manuals/BROWN/INDEX.HTM#bc6]
A4: Tag | B4: Definition | C4: En gold tagset
A5: . | B5: sentence (. ; ? *) | C5: =MATCH(A5,'gold tagset'!A:A,0) -> 10
A6: ( | B6: left paren | C6: =MATCH(A6,'gold tagset'!A:A,0) -> 7
A7: ) | B7: right paren | C7: =MATCH(A7,'gold tagset'!A:A,0) -> 8
A8: * | B8: not, n't | C8: =MATCH(A8,'gold tagset'!A:A,0) -> 2
A9: -- | B9: dash | C9: =MATCH(A9,'gold tagset'!A:A,0) -> 6
A10: , | B10: comma | C10: =MATCH(A10,'gold tagset'!A:A,0) -> 9
A11: : | B11: colon | C11: =MATCH(A11,'gold tagset'!A:A,0) -> #N/A
A12: ABL | B12: pre-qualifier (quite, rather) | C12: =MATCH(A12,'gold tagset'!A:A,0) -> #N/A
A13: ABN | B13: pre-quantifier (half, all) | C13: =MATCH(A13,'gold tagset'!A:A,0) -> 12
A14: ABX | B14: pre-quantifier (both) | C14: =MATCH(A14,'gold tagset'!A:A,0) -> #N/A
A15: AP | B15: post-determiner (many, several, next) | C15: =MATCH(A15,'gold tagset'!A:A,0) -> 13
A16: AT | B16: article (a, the, no) | C16: =MATCH(A16,'gold tagset'!A:A,0) -> 14
... A91: WRB | B91: wh- adverb (how, where, when) | C91: =MATCH(A91,'gold tagset'!A:A,0) -> #N/A
A94: Otras etiquetas gold
A96: '' | B96: begin quotation
A97: `` | B97: end quotation
A100: Etiquetas TnT
A101: Unk | B101: unknown

Sheet Universal tagset
A2: ADJ | B2: adjective
A3: ADP | B3: adposition
A4: ADV | B4: adverb
A5: AUX | B5: auxiliary
A6: CCONJ | B6: coordinating conjunction
A7: DET | B7: determiner
A8: INTJ | B8: interjection
A9: NOUN | B9: noun
A10: NUM | B10: numeral
A11: PART | B11: particle
A12: PRON | B12: pronoun
A13: PROPN | B13: proper noun
... A18: X | B18: other

Sheet Brown-Universal mapping
A1: https://www.nltk.org/_modules/nltk/tag/mapping.html
A2: http://code.google.com/p/universal-pos-tags/
A5: Brown | B5: Universal
A6: ' | B6: .
A7: '' | B7: .
A8: ( | B8: .
A9: (-HL | B9: .
A10: ) | B10: .
A11: )-HL | B11: .
A12: * | B12: ADV
A13: *-HL | B13: ADV
A14: *-NC | B14: ADV
A15: *-TL | B15: ADV
A16: , | B16: .
... A480: Unk | B480: Unknown
